//ERR58-CPP. Handle all exceptions thrown before main() begins executing
#include <iostream>

class MyStaticObject {
public:
    MyStaticObject() {
        // Constructor logic
    }

    ~MyStaticObject() noexcept {
        try {
            // Destructor logic that may throw exceptions
        } catch (const std::exception& e) {
            // Handle the exception from the destructor
            std::cerr << "Exception in destructor: " << e.what() << std::endl;
            // Perform necessary actions to handle the exception
        }
    }
};

MyStaticObject staticObject; // Static object

int main() {
    try {
        // Application logic
        // Code that may throw exceptions

        // Access the static object
        // This may invoke the destructor, and any exceptions will be handled there
    } catch (const std::exception& e) {
        // Handle exceptions thrown before or during main
        std::cerr << "Exception before or during main: " << e.what() << std::endl;
        // Perform necessary actions to handle the exception
        return EXIT_FAILURE;
    }

    return EXIT_SUCCESS;
}
